<mujoco model="chopstick_bot">
  <compiler angle="radian" balanceinertia="true" />
  <asset>
    <mesh name="motor_mesh" file="meshes/XL-430_new_coordinate_on_axis.STL" scale="0.001000 0.001000 0.001000" />
  </asset>
  <worldbody>
    <body name="base_motor_link" pos="0.000000 0.000000 0.330000" quat="1.000000 0.000000 0.000000 0.000000">
      <freejoint name="floating_base" />
      <site name="imu" pos="0.000000 0.000000 0.000000" quat="0.707107 0.000000 0.000000 0.707107" />
      <inertial pos="0.000000 -0.012000 0.000000" mass="0.065000" diaginertia="0.000017973854 0.000010661354 0.000016111875" />
      <geom type="mesh" mesh="motor_mesh" rgba="0.89804 0.91765 0.92941 1.0" contype="0" conaffinity="0" group="0" />
      <geom type="box" size="0.014250 0.023250 0.017000" pos="0.000000 -0.012000 0.000000" rgba="0.0 0.8 0.1 1.0" contype="0" conaffinity="0" group="1" />
      <body name="l_hip_pitch" pos="-0.040000 0.000000 0.000000" quat="0.707107 0.000000 -0.707107 0.000000">
        <inertial pos="0.000000 -0.012000 0.000000" mass="0.065000" diaginertia="0.000017973854 0.000010661354 0.000016111875" />
        <geom type="mesh" mesh="motor_mesh" rgba="0.89804 0.91765 0.92941 1.0" contype="0" conaffinity="0" group="0" />
        <geom type="box" size="0.014250 0.023250 0.017000" pos="0.000000 -0.012000 0.000000" rgba="0.0 0.8 0.1 1.0" contype="0" conaffinity="0" group="1" />
        <body name="l_hip_pitch_out" pos="0.000000 0.000000 0.000000" quat="1.000000 0.000000 0.000000 0.000000">
          <inertial pos="0.000000 0.000000 0.000000" mass="0.001000" diaginertia="0.000000016667 0.000000016667 0.000000016667" />
          <joint name="l_hip_pitch_joint" type="hinge" axis="0.000000 0.000000 1.000000" pos="0.000000 0.000000 0.000000" range="-3.14159 3.14159" damping="0.01" frictionloss="0.01" armature="0.02" />
          <body name="l_hip_roll" pos="0.000000 0.000000 0.040000" quat="0.500000 -0.500000 -0.500000 -0.500000">
            <inertial pos="0.000000 -0.012000 0.000000" mass="0.065000" diaginertia="0.000017973854 0.000010661354 0.000016111875" />
            <geom type="mesh" mesh="motor_mesh" rgba="0.89804 0.91765 0.92941 1.0" contype="0" conaffinity="0" group="0" />
            <geom type="box" size="0.014250 0.023250 0.017000" pos="0.000000 -0.012000 0.000000" rgba="0.0 0.8 0.1 1.0" contype="0" conaffinity="0" group="1" />
            <body name="l_hip_roll_out" pos="0.000000 0.000000 0.000000" quat="1.000000 0.000000 0.000000 0.000000">
              <inertial pos="0.000000 0.000000 0.000000" mass="0.001000" diaginertia="0.000000016667 0.000000016667 0.000000016667" />
              <joint name="l_hip_roll_joint" type="hinge" axis="0.000000 0.000000 1.000000" pos="0.000000 0.000000 0.000000" range="-3.14159 3.14159" damping="0.01" frictionloss="0.01" armature="0.02" />
              <body name="l_end_effector" pos="0.000000 -0.170000 0.000000" quat="1.000000 0.000000 0.000000 0.000000">
                <inertial pos="0.000000 0.000000 0.000000" mass="0.030000" diaginertia="0.000100187500 0.000100187500 0.000000375000" />
                <geom type="cylinder" size="0.005000 0.100000" pos="0.000000 0.000000 0.000000" quat="0.707107 0.707107 0.000000 0.000000" rgba="0.7 0.7 0.7 1.0" contype="0" conaffinity="0" group="0" />
                <geom name="left_foot" type="box" size="0.010000 0.010000 0.010000" pos="0.000000 -0.100000 0.000000" rgba="0.3 0.3 0.3 1.0" contype="1" conaffinity="1" group="1" />
                <site name="left_foot" pos="0.000000 0.000000 0.000000" quat="1.000000 0.000000 0.000000 0.000000" />
              </body>
            </body>
          </body>
        </body>
      </body>
      <body name="r_hip_pitch" pos="0.040000 0.000000 0.000000" quat="0.707107 0.000000 0.707107 0.000000">
        <inertial pos="0.000000 -0.012000 0.000000" mass="0.065000" diaginertia="0.000017973854 0.000010661354 0.000016111875" />
        <geom type="mesh" mesh="motor_mesh" rgba="0.89804 0.91765 0.92941 1.0" contype="0" conaffinity="0" group="0" />
        <geom type="box" size="0.014250 0.023250 0.017000" pos="0.000000 -0.012000 0.000000" rgba="0.0 0.8 0.1 1.0" contype="0" conaffinity="0" group="1" />
        <body name="r_hip_pitch_out" pos="0.000000 0.000000 0.000000" quat="1.000000 0.000000 0.000000 0.000000">
          <inertial pos="0.000000 0.000000 0.000000" mass="0.001000" diaginertia="0.000000016667 0.000000016667 0.000000016667" />
          <joint name="r_hip_pitch_joint" type="hinge" axis="0.000000 0.000000 1.000000" pos="0.000000 0.000000 0.000000" range="-3.14159 3.14159" damping="0.01" frictionloss="0.01" armature="0.02" />
          <body name="r_hip_roll" pos="-0.000000 0.000000 0.040000" quat="0.500000 -0.500000 0.500000 0.500000">
            <inertial pos="0.000000 -0.012000 0.000000" mass="0.065000" diaginertia="0.000017973854 0.000010661354 0.000016111875" />
            <geom type="mesh" mesh="motor_mesh" rgba="0.89804 0.91765 0.92941 1.0" contype="0" conaffinity="0" group="0" />
            <geom type="box" size="0.014250 0.023250 0.017000" pos="0.000000 -0.012000 0.000000" rgba="0.0 0.8 0.1 1.0" contype="0" conaffinity="0" group="1" />
            <body name="r_hip_roll_out" pos="0.000000 0.000000 0.000000" quat="1.000000 0.000000 0.000000 0.000000">
              <inertial pos="0.000000 0.000000 0.000000" mass="0.001000" diaginertia="0.000000016667 0.000000016667 0.000000016667" />
              <joint name="r_hip_roll_joint" type="hinge" axis="0.000000 0.000000 1.000000" pos="0.000000 0.000000 0.000000" range="-3.14159 3.14159" damping="0.01" frictionloss="0.01" armature="0.02" />
              <body name="r_end_effector" pos="-0.000000 -0.170000 0.000000" quat="1.000000 0.000000 0.000000 0.000000">
                <inertial pos="0.000000 0.000000 0.000000" mass="0.030000" diaginertia="0.000100187500 0.000100187500 0.000000375000" />
                <geom type="cylinder" size="0.005000 0.100000" pos="0.000000 0.000000 0.000000" quat="0.707107 0.707107 0.000000 0.000000" rgba="0.7 0.7 0.7 1.0" contype="0" conaffinity="0" group="0" />
                <geom name="right_foot" type="box" size="0.010000 0.010000 0.010000" pos="0.000000 -0.100000 0.000000" rgba="0.3 0.3 0.3 1.0" contype="1" conaffinity="1" group="1" />
                <site name="right_foot" pos="0.000000 0.000000 0.000000" quat="1.000000 0.000000 0.000000 0.000000" />
              </body>
            </body>
          </body>
        </body>
      </body>
      <body name="trunk_link" pos="0.000000 0.000000 0.050000" quat="1.000000 0.000000 0.000000 0.000000">
        <joint name="base_to_trunk" type="hinge" axis="0.000000 0.000000 1.000000" range="-3.14159 3.14159" damping="0.01" frictionloss="0.01" armature="0.02" />
        <inertial pos="0.000000 0.000000 0.000000" mass="0.200000" diaginertia="0.000083333333 0.000083333333 0.000083333333" />
        <geom type="box" size="0.025000 0.025000 0.025000" pos="0.000000 0.000000 0.000000" rgba="0.7 0.7 0.7 1.0" contype="0" conaffinity="0" group="0" />
      </body>
    </body>
  </worldbody>
  <actuator>
    <position name="l_hip_pitch" joint="l_hip_pitch_joint" kp="5" kv="0.0" ctrlrange="-3.14159 3.14159" />
    <position name="l_hip_roll" joint="l_hip_roll_joint" kp="5" kv="0.0" ctrlrange="-3.14159 3.14159" />
    <position name="r_hip_pitch" joint="r_hip_pitch_joint" kp="5" kv="0.0" ctrlrange="-3.14159 3.14159" />
    <position name="r_hip_roll" joint="r_hip_roll_joint" kp="5" kv="0.0" ctrlrange="-3.14159 3.14159" />
    <position name="base_to_trunk" joint="base_to_trunk" kp="5" kv="0.0" ctrlrange="-3.14159 3.14159" />
  </actuator>
  <sensor>
    <framepos name="position" objtype="site" objname="imu" noise="0.001" />
    <velocimeter name="linear-velocity" site="imu" noise="0.001" cutoff="30" />
    <framequat name="orientation" objtype="site" objname="imu" noise="0.001" />
    <gyro name="angular-velocity" site="imu" noise="0.005" cutoff="34.9" />
    <accelerometer name="linear-acceleration" site="imu" noise="0.005" cutoff="157" />
    <magnetometer name="magnetometer" site="imu" />
    <gyro site="imu" name="gyro" />
    <velocimeter site="imu" name="local_linvel" />
    <accelerometer site="imu" name="accelerometer" />
    <framezaxis objtype="site" objname="imu" name="upvector" />
    <framexaxis objtype="site" objname="imu" name="forwardvector" />
    <framelinvel objtype="site" objname="imu" name="global_linvel" />
    <frameangvel objtype="site" objname="imu" name="global_angvel" />
    <framelinvel objtype="site" objname="left_foot" name="left_foot_global_linvel" />
    <framelinvel objtype="site" objname="right_foot" name="right_foot_global_linvel" />
    <framepos objtype="site" objname="left_foot" name="left_foot_pos" />
    <framepos objtype="site" objname="right_foot" name="right_foot_pos" />
    <jointpos name="l_hip_pitch_joint_pos" joint="l_hip_pitch_joint" />
    <jointvel name="l_hip_pitch_joint_vel" joint="l_hip_pitch_joint" />
    <jointactuatorfrc name="l_hip_pitch_joint_frc" joint="l_hip_pitch_joint" />
    <jointpos name="r_hip_pitch_joint_pos" joint="r_hip_pitch_joint" />
    <jointvel name="r_hip_pitch_joint_vel" joint="r_hip_pitch_joint" />
    <jointactuatorfrc name="r_hip_pitch_joint_frc" joint="r_hip_pitch_joint" />
    <jointpos name="l_hip_roll_joint_pos" joint="l_hip_roll_joint" />
    <jointvel name="l_hip_roll_joint_vel" joint="l_hip_roll_joint" />
    <jointactuatorfrc name="l_hip_roll_joint_frc" joint="l_hip_roll_joint" />
    <jointpos name="r_hip_roll_joint_pos" joint="r_hip_roll_joint" />
    <jointvel name="r_hip_roll_joint_vel" joint="r_hip_roll_joint" />
    <jointactuatorfrc name="r_hip_roll_joint_frc" joint="r_hip_roll_joint" />
    <jointpos name="base_to_trunk_pos" joint="base_to_trunk" />
    <jointvel name="base_to_trunk_vel" joint="base_to_trunk" />
    <jointactuatorfrc name="base_to_trunk_frc" joint="base_to_trunk" />
  </sensor>
</mujoco>